<?xml version="1.0" ?>
<sdf version='1.11' xmlns:xacro='http://ros.org/wiki/xacro'>
  <model name='scout_mini'>

    <!-- Define some commonly used inertial properties  -->
    <xacro:macro name="box_inertia" params="m w h d">
      <inertial>
        <pose>0 0 0 ${pi/2} 0 ${pi/2}</pose>
        <mass>${m}</mass>
        <inertia>
          <ixx>${(m/12) * (h*h + d*d)}</ixx>
          <ixy>0.0</ixy>
          <ixz>0.0</ixz>
          <iyy>${(m/12) * (w*w + d*d)}</iyy>
          <iyz>0.0</iyz>
          <izz>${(m/12) * (w*w + h*h)}</izz>
        </inertia>
      </inertial>
    </xacro:macro>

    <xacro:macro name="cylinder_inertia" params="m r h">
      <inertial>
        <pose>0 0 0 ${pi/2} 0 0</pose>
        <mass>${m}</mass>
        <inertia>
          <ixx>${(m/12) * (3*r*r + h*h)}</ixx>
          <ixy>0.0</ixy>
          <ixz>0.0</ixz>
          <iyy>${(m/12) * (3*r*r + h*h)}</iyy>
          <iyz>0.0</iyz>
          <izz>${(m/2) * (r*r)}</izz>
        </inertia>
      </inertial>
    </xacro:macro>

    <xacro:macro name="sphere_inertia" params="m r">
      <inertial>
        <mass>${m}</mass>
        <inertia>
          <ixx>${(2/5) * m * (r*r)}</ixx>
          <ixy>0.0</ixy>
          <ixz>0.0</ixz>
          <iyy>${(2/5) * m * (r*r)}</iyy>
          <iyz>0.0</iyz>
          <izz>${(2/5) * m * (r*r)}</izz>
        </inertia>
      </inertial>
    </xacro:macro>

    <link name="base_footprint"/>

    <joint name="base_joint" type="fixed">
      <parent>base_footprint</parent>
      <child>base_link</child>
      <pose>0.0 0.0 0.010 0 0 0</pose>
    </joint>

    <link name='base_link'>
      <inertial>
        <pose>0 0 0 0 0 0</pose>
        <mass>60</mass>
        <inertia>
          <ixx>2.2886410000000001</ixx>
          <ixy>0</ixy>
          <ixz>0</ixz>
          <iyy>5.1039760000000003</iyy>
          <iyz>0</iyz>
          <izz>3.4314650000000002</izz>
        </inertia>
      </inertial>
      <collision name='base_link_collision'>
        <pose>0 0 0 1.5700000000000001 -5.5511151231257827e-17 1.5700000000000001</pose>
        <geometry>
          <mesh>
            <scale>1 1 1</scale>
            <uri>model://scout_mini_base_link2.dae</uri>
          </mesh>
        </geometry>
        <surface>
          <contact>
            <ode/>
          </contact>
          <friction>
            <ode>
              <mu>0.20000000000000001</mu>
              <mu2>0.20000000000000001</mu2>
            </ode>
          </friction>
        </surface>
      </collision>
      <visual name='base_link_visual'>
        <pose>0 0 0 1.5700000000000001 5.5511151231257827e-17 -1.5700000000000001</pose>
        <geometry>
          <mesh>
            <scale>1 1 1</scale>
            <uri>model://scout_mini_base_link2.dae</uri>
          </mesh>
        </geometry>
      </visual>
    </link>
    <joint name='front_left_wheel' type='revolute'>
      <pose relative_to='base_link'>0.2319755 0.20825150000000001 -0.100998 -1.5700000000000001 0 0</pose>
      <parent>base_link</parent>
      <child>front_left_wheel_link</child>
      <axis>
        <xyz>0 0 1</xyz>
        <limit>
          <lower>-inf</lower>
          <upper>inf</upper>
        </limit>
        <dynamics>
          <spring_reference>0</spring_reference>
          <spring_stiffness>0</spring_stiffness>
        </dynamics>
      </axis>
    </joint>
    <link name='front_left_wheel_link'>
      <pose relative_to='front_left_wheel'>0 0 0 0 0 0</pose>
      <inertial>
        <pose>0 0 0 0 0 0</pose>
        <mass>3</mass>
        <inertia>
          <ixx>0.71709999999999996</ixx>
          <ixy>0</ixy>
          <ixz>0</ixz>
          <iyy>0.71709999999999996</iyy>
          <iyz>0</iyz>
          <izz>0.1361</izz>
        </inertia>
      </inertial>
      <collision name='front_left_wheel_link_collision'>
        <pose>0 0 0 0 0 0</pose>
        <geometry>
          <mesh>
            <scale>1 1 1</scale>
            <uri>model://wheel.dae</uri>
          </mesh>
        </geometry>
        <surface>
          <contact>
            <ode/>
          </contact>
          <friction>
            <ode>
              <mu>0.20000000000000001</mu>
              <mu2>0.20000000000000001</mu2>
            </ode>
          </friction>
        </surface>
      </collision>
      <visual name='front_left_wheel_link_visual'>
        <pose>0 0 0 0 0 0</pose>
        <geometry>
          <mesh>
            <scale>1 1 1</scale>
            <uri>model://wheel.dae</uri>
          </mesh>
        </geometry>
      </visual>
    </link>
    <joint name='front_right_wheel' type='revolute'>
      <pose relative_to='base_link'>0.2319755 -0.20825150000000001 -0.099998000000000004 1.5700000000000001 0 0</pose>
      <parent>base_link</parent>
      <child>front_right_wheel_link</child>
      <axis>
        <xyz>0 0 -1</xyz>
        <limit>
          <lower>-inf</lower>
          <upper>inf</upper>
        </limit>
        <dynamics>
          <spring_reference>0</spring_reference>
          <spring_stiffness>0</spring_stiffness>
        </dynamics>
      </axis>
    </joint>
    <link name='front_right_wheel_link'>
      <pose relative_to='front_right_wheel'>0 0 0 0 0 0</pose>
      <inertial>
        <pose>0 0 0 0 0 0</pose>
        <mass>3</mass>
        <inertia>
          <ixx>0.71709999999999996</ixx>
          <ixy>0</ixy>
          <ixz>0</ixz>
          <iyy>0.71709999999999996</iyy>
          <iyz>0</iyz>
          <izz>0.1361</izz>
        </inertia>
      </inertial>
      <collision name='front_right_wheel_link_collision'>
        <pose>0 0 0 0 0 0</pose>
        <geometry>
          <mesh>
            <scale>1 1 1</scale>
            <uri>model://wheel.dae</uri>
          </mesh>
        </geometry>
        <surface>
          <contact>
            <ode/>
          </contact>
          <friction>
            <ode>
              <mu>0.20000000000000001</mu>
              <mu2>0.20000000000000001</mu2>
            </ode>
          </friction>
        </surface>
      </collision>
      <visual name='front_right_wheel_link_visual'>
        <pose>0 0 0 0 0 0</pose>
        <geometry>
          <mesh>
            <scale>1 1 1</scale>
            <uri>model://wheel.dae</uri>
          </mesh>
        </geometry>
      </visual>
    </link>
    <joint name='rear_left_wheel' type='revolute'>
      <pose relative_to='base_link'>-0.2319755 0.20825150000000001 -0.100998 -1.5700000000000001 0 0</pose>
      <parent>base_link</parent>
      <child>rear_left_wheel_link</child>
      <axis>
        <xyz>0 0 1</xyz>
        <limit>
          <lower>-inf</lower>
          <upper>inf</upper>
        </limit>
        <dynamics>
          <spring_reference>0</spring_reference>
          <spring_stiffness>0</spring_stiffness>
        </dynamics>
      </axis>
    </joint>
    <link name='rear_left_wheel_link'>
      <pose relative_to='rear_left_wheel'>0 0 0 0 0 0</pose>
      <inertial>
        <pose>0 0 0 0 0 0</pose>
        <mass>3</mass>
        <inertia>
          <ixx>0.71709999999999996</ixx>
          <ixy>0</ixy>
          <ixz>0</ixz>
          <iyy>0.71709999999999996</iyy>
          <iyz>0</iyz>
          <izz>0.1361</izz>
        </inertia>
      </inertial>
      <collision name='rear_left_wheel_link_collision'>
        <pose>0 0 0 0 0 0</pose>
        <geometry>
          <mesh>
            <scale>1 1 1</scale>
            <uri>model://wheel.dae</uri>
          </mesh>
        </geometry>
        <surface>
          <contact>
            <ode/>
          </contact>
          <friction>
            <ode>
              <mu>0.20000000000000001</mu>
              <mu2>0.20000000000000001</mu2>
            </ode>
          </friction>
        </surface>
      </collision>
      <visual name='rear_left_wheel_link_visual'>
        <pose>0 0 0 0 0 0</pose>
        <geometry>
          <mesh>
            <scale>1 1 1</scale>
            <uri>model://wheel.dae</uri>
          </mesh>
        </geometry>
      </visual>
    </link>
    <joint name='rear_right_wheel' type='revolute'>
      <pose relative_to='base_link'>-0.2319755 -0.20825150000000001 -0.099998000000000004 1.5700000000000001 0 0</pose>
      <parent>base_link</parent>
      <child>rear_right_wheel_link</child>
      <axis>
        <xyz>0 0 -1</xyz>
        <limit>
          <lower>-inf</lower>
          <upper>inf</upper>
        </limit>
        <dynamics>
          <spring_reference>0</spring_reference>
          <spring_stiffness>0</spring_stiffness>
        </dynamics>
      </axis>
    </joint>
    <link name='rear_right_wheel_link'>
      <pose relative_to='rear_right_wheel'>0 0 0 0 0 0</pose>
      <inertial>
        <pose>0 0 0 0 0 0</pose>
        <mass>3</mass>
        <inertia>
          <ixx>0.71709999999999996</ixx>
          <ixy>0</ixy>
          <ixz>0</ixz>
          <iyy>0.71709999999999996</iyy>
          <iyz>0</iyz>
          <izz>0.1361</izz>
        </inertia>
      </inertial>
      <collision name='rear_right_wheel_link_collision'>
        <pose>0 0 0 0 0 0</pose>
        <geometry>
          <mesh>
            <scale>1 1 1</scale>
            <uri>model://wheel.dae</uri>
          </mesh>
        </geometry>
        <surface>
          <contact>
            <ode/>
          </contact>
          <friction>
            <ode>
              <mu>0.20000000000000001</mu>
              <mu2>0.20000000000000001</mu2>
            </ode>
          </friction>
        </surface>
      </collision>
      <visual name='rear_right_wheel_link_visual'>
        <pose>0 0 0 0 0 0</pose>
        <geometry>
          <mesh>
            <scale>1 1 1</scale>
            <uri>model://wheel.dae</uri>
          </mesh>
        </geometry>
      </visual>
    </link>

    <plugin name='gz::sim::systems::DiffDrive' filename='gz-sim-diff-drive-system'>
      <left_joint>front_left_wheel</left_joint>
      <right_joint>front_right_wheel</right_joint>
      <left_joint>rear_left_wheel</left_joint>
      <right_joint>rear_right_wheel</right_joint>

      <wheel_separation>0.451</wheel_separation>
      <wheel_radius>0.08</wheel_radius>

      <max_linear_acceleration>0.033</max_linear_acceleration>

      <topic>cmd_vel</topic>

      <odom_topic>odom</odom_topic>
      <frame_id>odom</frame_id>
      <child_frame_id>base_footprint</child_frame_id>
      <odom_publisher_frequency>30</odom_publisher_frequency>
      
      <!-- <tf_topic>/tf</tf_topic> -->
    </plugin>


    <plugin
      filename="gz-sim-pose-publisher-system"
      name="gz::sim::systems::PosePublisher">
      <use_pose_vector_msg>true</use_pose_vector_msg>
      <publish_nested_model_pose>true</publish_nested_model_pose>
    </plugin>


    <plugin name='gz::sim::systems::JointStatePublisher' filename='gz-sim-joint-state-publisher-system'>
      <topic>joint_states</topic>
      <joint_name>front_left_wheel</joint_name>
      <joint_name>front_right_wheel</joint_name>
      <joint_name>rear_left_wheel</joint_name>
      <joint_name>rear_right_wheel</joint_name>
    </plugin>
    
    <frame name='inertial_joint' attached_to='base_link'>
      <pose>0 0 0 0 0 0</pose>
    </frame>
    <frame name='inertial_link' attached_to='inertial_joint'>
      <pose>0 0 0 0 0 0</pose>
    </frame>

    <joint name='imu_joint' type='fixed'>
      <parent>base_link</parent>
      <child>imu_link</child>
      <pose relative_to="base_link">0.0 0.0 0.01 0 0 0</pose>
    </joint>

    <link name='imu_link'>
      <pose relative_to="imu_joint"/>
      <visual name="imu_link_visual">
        <geometry>
          <box><size>
            0.1 0.1 0.1
          </size></box>
        </geometry>
      </visual>

      <collision name="imu_link_collision">
        <geometry>
          <box><size>
            0.1 0.1 0.1
          </size></box>
        </geometry>
      </collision>

      <xacro:box_inertia m="0.1" w="0.1" d="0.1" h="0.1"/>

      <sensor name="imu_sensor" type="imu">
        <always_on>true</always_on>
        <update_rate>100</update_rate>
        <visualize>true</visualize>
        <topic>imu</topic>
        <gz_frame_id>imu_link</gz_frame_id>
        <imu>
          <angular_velocity>
            <x>
              <noise type="gaussian">
                <mean>0.0</mean>
                <stddev>2e-4</stddev>
                <bias_mean>0.0000075</bias_mean>
                <bias_stddev>0.0000008</bias_stddev>
              </noise>
            </x>
            <y>
              <noise type="gaussian">
                <mean>0.0</mean>
                <stddev>2e-4</stddev>
                <bias_mean>0.0000075</bias_mean>
                <bias_stddev>0.0000008</bias_stddev>
              </noise>
            </y>
            <z>
              <noise type="gaussian">
                <mean>0.0</mean>
                <stddev>2e-4</stddev>
                <bias_mean>0.0000075</bias_mean>
                <bias_stddev>0.0000008</bias_stddev>
              </noise>
            </z>
          </angular_velocity>
          <linear_acceleration>
            <x>
              <noise type="gaussian">
                <mean>0.0</mean>
                <stddev>1.7e-2</stddev>
                <bias_mean>0.1</bias_mean>
                <bias_stddev>0.001</bias_stddev>
              </noise>
            </x>
            <y>
              <noise type="gaussian">
                <mean>0.0</mean>
                <stddev>1.7e-2</stddev>
                <bias_mean>0.1</bias_mean>
                <bias_stddev>0.001</bias_stddev>
              </noise>
            </y>
            <z>
              <noise type="gaussian">
                <mean>0.0</mean>
                <stddev>1.7e-2</stddev>
                <bias_mean>0.1</bias_mean>
                <bias_stddev>0.001</bias_stddev>
              </noise>
            </z>
          </linear_acceleration>
        </imu>
      </sensor>
    </link>

    <joint name="lidar_joint" type="fixed">
      <parent>base_link</parent>
      <child>lidar_link</child>
      <pose relative_to="base_link">0.0 0.0 0.3 0 0 0</pose>
    </joint>

    <link name='lidar_link'>
      <pose relative_to="lidar_joint"/>
      <visual name="lidar_link_visual">
        <geometry>
          <cylinder>
            <radius>0.0508</radius>
            <length>0.055</length>
          </cylinder>
        </geometry>
      </visual>

      <collision name="lidar_link_collision">
        <geometry>
          <cylinder>
            <radius>0.0508</radius>
            <length>0.055</length>
          </cylinder>
        </geometry>
      </collision>

      <xacro:cylinder_inertia m="0.125" r="0.0508" h="0.055"/>

      <sensor name="lidar" type="gpu_lidar">
        <always_on>true</always_on>
        <visualize>true</visualize>
        <update_rate>5</update_rate>
        <topic>scan</topic>
        <gz_frame_id>lidar_link</gz_frame_id>
        <lidar>
          <scan>
            <horizontal>
              <samples>360</samples>
              <resolution>1.000000</resolution>
              <min_angle>0.000000</min_angle>
              <max_angle>6.280000</max_angle>
            </horizontal>
          </scan>
          <range>
            <min>0.120000</min>
            <max>3.5</max>
            <resolution>0.015000</resolution>
          </range>
          <noise>
            <type>gaussian</type>
            <mean>0.0</mean>
            <stddev>0.01</stddev>
          </noise>
        </lidar>
      </sensor>
    </link>

    <!-- <joint name="camera_joint" type="fixed">
      <parent>base_link</parent>
      <child>camera_link</child>
      <pose relative_to="base_link">0.215 0 0.05 0 0 0</pose>
    </joint> -->

    <!-- <link name='camera_link'>
      <pose relative_to="camera_joint"/>
      <visual name="camera_link_visual">
        <geometry>
          <box><size>
            0.015 0.130 0.0222
          </size></box>
        </geometry>
      </visual>

      <collision name="camera_link_collision">
        <geometry>
          <box><size>
            0.015 0.130 0.0222
          </size></box>
        </geometry>
      </collision>

      <xacro:box_inertia m="0.035" w="0.015" d="0.130" h="0.0222"/>

      <sensor name="depth_camera" type="rgbd_camera">
        <always_on>true</always_on>
        <visualize>true</visualize>
        <update_rate>5.0</update_rate>
        <topic>depth_camera</topic>
        <gz_frame_id>camera_link</gz_frame_id>
        <camera>
          <horizontal_fov>1.047198</horizontal_fov>
          <image>
            <width>640</width>
            <height>480</height>
          </image>
          <clip>
            <near>0.05</near>
            <far>3</far>
          </clip>
        </camera>
        <baseline>0.2</baseline>
        <pointCloudCutoff>0.5</pointCloudCutoff>
        <pointCloudCutoffMax>3.0</pointCloudCutoffMax>
        <distortionK1>0</distortionK1>
        <distortionK2>0</distortionK2>
        <distortionK3>0</distortionK3>
        <distortionT1>0</distortionT1>
        <distortionT2>0</distortionT2>
        <CxPrime>0</CxPrime>
        <Cx>0</Cx>
        <Cy>0</Cy>
        <focalLength>0</focalLength>
        <hackBaseline>0</hackBaseline>
      </sensor>
    </link> -->
  </model>
</sdf>
